Workbook

Sheet Read Me
B2: Chainlink Labs | LTI transition model | Option 1 and Option 2
B3: Confidential, internal compensation strategy. Index: annual LTI target = 100.
B5: The two designs
B6: Option 1 grant and refreshes 100/15/5/5. Steady state 125.
B7: Option 2 new hire 100/50 at 1.15x. Refresh half = 0.5 x the person's target.
B8: New hires settle at 115, existing employees keep 125, promoted people 230.
B10: RULES - normal year
B11: Option 1 one grant a year, full size. Y1 delivers 100, then 15 / 5 / 5.
B12: Option 2 one grant a year, full size. Half this year and half next year, where the
B13: half is 0.5 x target: 57.5 for a new hire, 62.5 for an existing employee,
B14: 115 once promoted.
B15: Nothing is netted against what is already vesting. The grant is the same for everyone
... B77: LTI_Vesting_Model_PRD_v11.md s6.1 to s6.4, s7.3, s12.1 registry. session_handoff.md s11.

Sheet Summary
B2: Summary
B3: Index: annual LTI target = 100. Face = total grant value issued 2027 to 2035.
B5: Cost comparison total grant face issued | D5: Option 1 | E5: Option 2 | F5: O2 - O1 | G5: O2 vs O1
B6: Base
B7: Persona A | D7: =Base!M18 -> 1125 | E7: =Base!Z18 -> 1092.5 | F7: =E7-D7 -> -32.5 | G7: =IF(D7=0,"",E7/D7-1) -> -0.028888889
B8: Persona B | D8: =Base!M38 -> 883.75 | E8: =Base!Z37 -> 887.5 | F8: =E8-D8 -> 3.75 | G8: =IF(D8=0,"",E8/D8-1) -> 0.0042432815
B9: Persona C | D9: =Base!M58 -> 858.75 | E9: =Base!Z58 -> 862.5 | F9: =E9-D9 -> 3.75 | G9: =IF(D9=0,"",E9/D9-1) -> 0.0043668122
B10: Persona D | D10: =Base!M78 -> 833.75 | E10: =Base!Z77 -> 837.5 | F10: =E10-D10 -> 3.75 | G10: =IF(D10=0,"",E10/D10-1) -> 0.0044977511
B11: Persona E | D11: =Base!M98 -> 808.75 | E11: =Base!Z97 -> 812.5 | F11: =E11-D11 -> 3.75 | G11: =IF(D11=0,"",E11/D11-1) -> 0.0046367852
B12: Persona F | D12: =Base!M118 -> 1115 | E12: =Base!Z117 -> 1137.5 | F12: =E12-D12 -> 22.5 | G12: =IF(D12=0,"",E12/D12-1) -> 0.020179372
B13: Persona G | D13: =Base!M138 -> 1090 | E13: =Base!Z137 -> 1112.5 | F13: =E13-D13 -> 22.5 | G13: =IF(D13=0,"",E13/D13-1) -> 0.020642202
B14: Persona H | D14: =Base!M158 -> 971.25 | E14: =Base!Z157 -> 987.5 | F14: =E14-D14 -> 16.25 | G14: =IF(D14=0,"",E14/D14-1) -> 0.016731017
B15: Total, all personas | D15: =SUM(D7:D14) -> 7686.25 | E15: =SUM(E7:E14) -> 7730 | F15: =SUM(F7:F14) -> 43.75 | G15: =IF(D15=0,"",E15/D15-1) -> 0.0056919824
B17: Promo in T
B18: Persona A | D18: ='Promo in T'!M18 -> 2000 | E18: ='Promo in T'!Z18 -> 1955 | F18: =E18-D18 -> -45 | G18: =IF(D18=0,"",E18/D18-1) -> -0.0225
B19: Persona B | D19: ='Promo in T'!M37 -> 1593.75 | E19: ='Promo in T'!Z37 -> 1570 | F19: =E19-D19 -> -23.75 | G19: =IF(D19=0,"",E19/D19-1) -> -0.014901961
B20: Persona C | D20: ='Promo in T'!M56 -> 1562.5 | E20: ='Promo in T'!Z57 -> 1545 | F20: =E20-D20 -> -17.5 | G20: =IF(D20=0,"",E20/D20-1) -> -0.0112
B21: Persona D | D21: ='Promo in T'!M76 -> 1531.25 | E21: ='Promo in T'!Z77 -> 1520 | F21: =E21-D21 -> -11.25 | G21: =IF(D21=0,"",E21/D21-1) -> -0.0073469388
B22: Persona E | D22: ='Promo in T'!M96 -> 1500 | E22: ='Promo in T'!Z97 -> 1495 | F22: =E22-D22 -> -5 | G22: =IF(D22=0,"",E22/D22-1) -> -0.0033333333
B23: Persona F | D23: ='Promo in T'!M116 -> 2187.5 | E23: ='Promo in T'!Z117 -> 2135 | F23: =E23-D23 -> -52.5 | G23: =IF(D23=0,"",E23/D23-1) -> -0.024
B24: Persona G | D24: ='Promo in T'!M136 -> 2156.25 | E24: ='Promo in T'!Z137 -> 2110 | F24: =E24-D24 -> -46.25 | G24: =IF(D24=0,"",E24/D24-1) -> -0.021449275
B25: Persona H | D25: ='Promo in T'!M156 -> 1875 | E25: ='Promo in T'!Z156 -> 1855 | F25: =E25-D25 -> -20 | G25: =IF(D25=0,"",E25/D25-1) -> -0.010666667
B26: Total, all personas | D26: =SUM(D18:D25) -> 14406.25 | E26: =SUM(E18:E25) -> 14185 | F26: =SUM(F18:F25) -> -221.25 | G26: =IF(D26=0,"",E26/D26-1) -> -0.015357918
B28: Promo before T
B29: Persona B | D29: ='Promo before T'!M22 -> 1687.5 | E29: ='Promo before T'!Z22 -> 1675 | F29: =E29-D29 -> -12.5 | G29: =IF(D29=0,"",E29/D29-1) -> -0.0074074074
B30: Persona C | D30: ='Promo before T'!M41 -> 1656.25 | E30: ='Promo before T'!Z42 -> 1650 | F30: =E30-D30 -> -6.25 | G30: =IF(D30=0,"",E30/D30-1) -> -0.0037735849
B31: Persona D | D31: ='Promo before T'!M61 -> 1625 | E31: ='Promo before T'!Z62 -> 1625 | F31: =E31-D31 -> 0 | G31: =IF(D31=0,"",E31/D31-1) -> 0
B32: Persona E | D32: ='Promo before T'!M81 -> 1593.75 | E32: ='Promo before T'!Z82 -> 1600 | F32: =E32-D32 -> 6.25 | G32: =IF(D32=0,"",E32/D32-1) -> 0.0039215686
B33: Persona H | D33: ='Promo before T'!M109 -> 1906.25 | E33: ='Promo before T'!Z109 -> 1910 | F33: =E33-D33 -> 3.75 | G33: =IF(D33=0,"",E33/D33-1) -> 0.0019672131
B34: Total, all personas | D34: =SUM(D29:D33) -> 8468.75 | E34: =SUM(E29:E33) -> 8460 | F34: =SUM(F29:F33) -> -8.75 | G34: =IF(D34=0,"",E34/D34-1) -> -0.0010332103
B36: Outsized 1.5x in 2030
B37: Persona A | D37: ='Outsized 1.5x in 2030'!M18 -> 1187.5 | E37: ='Outsized 1.5x in 2030'!Z18 -> 1162.5 | F37: =E37-D37 -> -25 | G37: =IF(D37=0,"",E37/D37-1) -> -0.021052632
B38: Persona B | D38: ='Outsized 1.5x in 2030'!M38 -> 908.75 | E38: ='Outsized 1.5x in 2030'!Z37 -> 925 | F38: =E38-D38 -> 16.25 | G38: =IF(D38=0,"",E38/D38-1) -> 0.017881706
B39: Persona C | D39: ='Outsized 1.5x in 2030'!M58 -> 883.75 | E39: ='Outsized 1.5x in 2030'!Z58 -> 887.5 | F39: =E39-D39 -> 3.75 | G39: =IF(D39=0,"",E39/D39-1) -> 0.0042432815
B40: Persona D | D40: ='Outsized 1.5x in 2030'!M78 -> 858.75 | E40: ='Outsized 1.5x in 2030'!Z78 -> 862.5 | F40: =E40-D40 -> 3.75 | G40: =IF(D40=0,"",E40/D40-1) -> 0.0043668122
B41: Persona E | D41: ='Outsized 1.5x in 2030'!M98 -> 833.75 | E41: ='Outsized 1.5x in 2030'!Z97 -> 875 | F41: =E41-D41 -> 41.25 | G41: =IF(D41=0,"",E41/D41-1) -> 0.049475262
B42: Persona F | D42: ='Outsized 1.5x in 2030'!M118 -> 1177.5 | E42: ='Outsized 1.5x in 2030'!Z117 -> 1187.5 | F42: =E42-D42 -> 10 | G42: =IF(D42=0,"",E42/D42-1) -> 0.008492569
B43: Persona G | D43: ='Outsized 1.5x in 2030'!M138 -> 1152.5 | E43: ='Outsized 1.5x in 2030'!Z137 -> 1162.5 | F43: =E43-D43 -> 10 | G43: =IF(D43=0,"",E43/D43-1) -> 0.0086767896
B44: Persona H | D44: ='Outsized 1.5x in 2030'!M158 -> 1033.75 | E44: ='Outsized 1.5x in 2030'!Z157 -> 1037.5 | F44: =E44-D44 -> 3.75 | G44: =IF(D44=0,"",E44/D44-1) -> 0.0036275695
B45: Total, all personas | D45: =SUM(D37:D44) -> 8036.25 | E45: =SUM(E37:E44) -> 8100 | F45: =SUM(F37:F44) -> 63.75 | G45: =IF(D45=0,"",E45/D45-1) -> 0.0079328045
...

Sheet Assumptions
B2: Assumptions
B3: Blue = input. Yellow = key assumption to confirm with Finance.
B5: Annual LTI target (index) | C5: 100 | I5: All figures are % of the annual LTI target.
B6: Base ceiling (x target) | C6: 1.25 | I6: Steady state, and the transition-year gap target.
B7: High-perf multiplier (x target) | C7: 1.5 | I7: Opt 1: grant Y1 = 150. Opt 2: gap target = 150.
B8: Opt 1 promotion (x target) | C8: 2 | I8: Promo-year gap target 200, then refreshes 200/30/10/10.
B9: Opt 2 new-hire premium (x target) | C9: 1.15 | I9: Persona A only. NHG = 115 / 57.5.
B10: Opt 2 promotion target | C10: 230 | I10: 2 x 115. Applies to every persona once promoted.
B11: Opt 2 refresh factor (x target) | C11: 0.5 | I11: Refresh half = this x the person's target: 57.5 / 62.5 / 115.
B12: Floor on gap grants (x target) | C12: 0.25 | I12: Applies in T and pre-T years. Perf multiplier applies on top.
B13: Pre-transition tail toggle | C13: 1 | I13: Option 1 only. Covers pre-transition top-ups AND promo grants in or before T. 1 = 100/15/5/5. 0 = one-year.
B16: Delivery vectors (multiples of the sizing column) | C16: Year 1 | D16: Year 2 | E16: Year 3 | F16: Year 4 | G16: Face / sizing
B17: Opt 1 shaped 100/15/5/5 | C17: 1 | D17: 0.15 | E17: 0.05 | F17: 0.05 | G17: 1.25 | I17: New hire, refresh and promo grants.
B18: Opt 2 two-year equal | C18: 1 | D18: 1 | E18: 0 | F18: 0 | G18: 2 | I18: Half now, half next year. Half = 0.5 x target.
B19: Opt 2 100/50 | C19: 1 | D19: 0.5 | E19: 0 | F19: 0 | G19: 1.5 | I19: New hire, collapsed transition grant, post-promo grant.
B20: Opt 2 100/50 starting T+1 | C20: 0 | D20: 1 | E20: 0.5 | F20: 0 | G20: 1.5 | I20: Used when legacy leaves no room in T.
B21: One-year grant | C21: 1 | D21: 0 | E21: 0 | F21: 0 | G21: 1 | I21: Pre-transition top-up and transition Grant 1.
B22: Opt 1 transition tail | C22: 0 | D22: 0.25 | E22: 0.1 | F22: 0.05 | G22: 0.4 | I22: Sizing column holds target. Never perf-scaled.
B23: Opt 1 pre-transition / promo grant | C23: 1 | D23: =IF(Assumptions!$C$13=1,0.15,0) -> 0.15 | E23: =IF(Assumptions!$C$13=1,0.05,0) -> 0.05 | F23: =IF(Assumptions!$C$13=1,0.05,0) -> 0.05 | G23: =IF(Assumptions!$C$13=1,1.25,1) -> 1.25 | I23: Driven by the tail toggle above.
B25: Personas and transition year T
B26: Persona A | C26: 2027 | I26: new hire 2027, no legacy grant
B27: Persona B | C27: 2030 | I27: hired 2026, 0 of target vesting in the transition year
B28: Persona C | C28: 2030 | I28: hired 2026, 25 of target vesting in the transition year
B29: Persona D | C29: 2030 | I29: hired 2026, 50 of target vesting in the transition year
B30: Persona E | C30: 2030 | I30: hired 2026, 75 of target vesting in the transition year
B31: Persona F | C31: 2027 | I31: hired 2023, 50 of target vesting in the transition year
B32: Persona G | C32: 2027 | I32: hired 2023, 75 of target vesting in the transition year
B33: Persona H | C33: 2028 | I33: hired 2024, 125 of target vesting in the transition year

Sheet Base
B2: Scenario: Base
B3: Grants in rows, years in columns. Option 1 left, Option 2 right. Index: annual LTI target = 100.
B5: Persona A new hire 2027, no legacy grant transition year 2027
B6: Option 1 100/15/5/5 | C6: Sizing | D6: 2027 | E6: 2028 | F6: 2029 | G6: 2030 | H6: 2031 | I6: 2032 | J6: 2033 | K6: 2034 | L6: 2035 | M6: Face | O6: Option 2 100/50 and 50/50 | P6: Sizing | Q6: 2027 | R6: 2028 | S6: 2029 | T6: 2030 | U6: 2031 | V6: 2032 | W6: 2033 | X6: 2034 | Y6: 2035 | Z6: Face
B7: Gap target (used only in T and promo years) | D7: =Assumptions!$C$5*Assumptions!$C$6 -> 125 | E7: =Assumptions!$C$5*Assumptions!$C$6 -> 125 | F7: =Assumptions!$C$5*Assumptions!$C$6 -> 125 | G7: =Assumptions!$C$5*Assumptions!$C$6 -> 125 | H7: =Assumptions!$C$5*Assumptions!$C$6 -> 125 | I7: =Assumptions!$C$5*Assumptions!$C$6 -> 125 | J7: =Assumptions!$C$5*Assumptions!$C$6 -> 125 | K7: =Assumptions!$C$5*Assumptions!$C$6 -> 125 | L7: =Assumptions!$C$5*Assumptions!$C$6 -> 125 | O7: Gap target (used only in T and promo years) | Q7: =Assumptions!$C$5*Assumptions!$C$6 -> 125 | R7: =Assumptions!$C$5*Assumptions!$C$6 -> 125 | S7: =Assumptions!$C$5*Assumptions!$C$6 -> 125 | T7: =Assumptions!$C$5*Assumptions!$C$6 -> 125 | U7: =Assumptions!$C$5*Assumptions!$C$6 -> 125 | V7: =Assumptions!$C$5*Assumptions!$C$6 -> 125 | W7: =Assumptions!$C$5*Assumptions!$C$6 -> 125 | X7: =Assumptions!$C$5*Assumptions!$C$6 -> 125 | Y7: =Assumptions!$C$5*Assumptions!$C$6 -> 125
B8: Legacy scheduled vest | D8: 0 | E8: 0 | F8: 0 | G8: 0 | H8: 0 | I8: 0 | J8: 0 | K8: 0 | L8: 0 | O8: Legacy scheduled vest | Q8: 0 | R8: 0 | S8: 0 | T8: 0 | U8: 0 | V8: 0 | W8: 0 | X8: 0 | Y8: 0
B9: 2027 new hire 100/15/5/5 | C9: =Assumptions!$C$5 -> 100 | D9: =$C9*Assumptions!$C$17 -> 100 | E9: =$C9*Assumptions!$D$17 -> 15 | F9: =$C9*Assumptions!$E$17 -> 5 | G9: =$C9*Assumptions!$F$17 -> 5 | M9: =$C9*Assumptions!$G$17 -> 125 | O9: 2027 new hire 100/50 at 1.15x | P9: =Assumptions!$C$5*Assumptions!$C$9 -> 115 | Q9: =$P9*Assumptions!$C$19 -> 115 | R9: =$P9*Assumptions!$D$19 -> 57.5 | S9: =$P9*Assumptions!$E$19 -> 0 | T9: =$P9*Assumptions!$F$19 -> 0 | Z9: =$P9*Assumptions!$G$19 -> 172.5
B10: 2028 refresh 100/15/5/5 | C10: =Assumptions!$C$5 -> 100 | E10: =$C10*Assumptions!$C$17 -> 100 | F10: =$C10*Assumptions!$D$17 -> 15 | G10: =$C10*Assumptions!$E$17 -> 5 | H10: =$C10*Assumptions!$F$17 -> 5 | M10: =$C10*Assumptions!$G$17 -> 125 | O10: 2028 refresh 50/50 at 115 | P10: =Assumptions!$C$11*Assumptions!$C$5*Assumptions!$C$9 -> 57.5 | R10: =$P10*Assumptions!$C$18 -> 57.5 | S10: =$P10*Assumptions!$D$18 -> 57.5 | T10: =$P10*Assumptions!$E$18 -> 0 | U10: =$P10*Assumptions!$F$18 -> 0 | Z10: =$P10*Assumptions!$G$18 -> 115
B11: 2029 refresh 100/15/5/5 | C11: =Assumptions!$C$5 -> 100 | F11: =$C11*Assumptions!$C$17 -> 100 | G11: =$C11*Assumptions!$D$17 -> 15 | H11: =$C11*Assumptions!$E$17 -> 5 | I11: =$C11*Assumptions!$F$17 -> 5 | M11: =$C11*Assumptions!$G$17 -> 125 | O11: 2029 refresh 50/50 at 115 | P11: =Assumptions!$C$11*Assumptions!$C$5*Assumptions!$C$9 -> 57.5 | S11: =$P11*Assumptions!$C$18 -> 57.5 | T11: =$P11*Assumptions!$D$18 -> 57.5 | U11: =$P11*Assumptions!$E$18 -> 0 | V11: =$P11*Assumptions!$F$18 -> 0 | Z11: =$P11*Assumptions!$G$18 -> 115
B12: 2030 refresh 100/15/5/5 | C12: =Assumptions!$C$5 -> 100 | G12: =$C12*Assumptions!$C$17 -> 100 | H12: =$C12*Assumptions!$D$17 -> 15 | I12: =$C12*Assumptions!$E$17 -> 5 | J12: =$C12*Assumptions!$F$17 -> 5 | M12: =$C12*Assumptions!$G$17 -> 125 | O12: 2030 refresh 50/50 at 115 | P12: =Assumptions!$C$11*Assumptions!$C$5*Assumptions!$C$9 -> 57.5 | T12: =$P12*Assumptions!$C$18 -> 57.5 | U12: =$P12*Assumptions!$D$18 -> 57.5 | V12: =$P12*Assumptions!$E$18 -> 0 | W12: =$P12*Assumptions!$F$18 -> 0 | Z12: =$P12*Assumptions!$G$18 -> 115
B13: 2031 refresh 100/15/5/5 | C13: =Assumptions!$C$5 -> 100 | H13: =$C13*Assumptions!$C$17 -> 100 | I13: =$C13*Assumptions!$D$17 -> 15 | J13: =$C13*Assumptions!$E$17 -> 5 | K13: =$C13*Assumptions!$F$17 -> 5 | M13: =$C13*Assumptions!$G$17 -> 125 | O13: 2031 refresh 50/50 at 115 | P13: =Assumptions!$C$11*Assumptions!$C$5*Assumptions!$C$9 -> 57.5 | U13: =$P13*Assumptions!$C$18 -> 57.5 | V13: =$P13*Assumptions!$D$18 -> 57.5 | W13: =$P13*Assumptions!$E$18 -> 0 | X13: =$P13*Assumptions!$F$18 -> 0 | Z13: =$P13*Assumptions!$G$18 -> 115
B14: 2032 refresh 100/15/5/5 | C14: =Assumptions!$C$5 -> 100 | I14: =$C14*Assumptions!$C$17 -> 100 | J14: =$C14*Assumptions!$D$17 -> 15 | K14: =$C14*Assumptions!$E$17 -> 5 | L14: =$C14*Assumptions!$F$17 -> 5 | M14: =$C14*Assumptions!$G$17 -> 125 | O14: 2032 refresh 50/50 at 115 | P14: =Assumptions!$C$11*Assumptions!$C$5*Assumptions!$C$9 -> 57.5 | V14: =$P14*Assumptions!$C$18 -> 57.5 | W14: =$P14*Assumptions!$D$18 -> 57.5 | X14: =$P14*Assumptions!$E$18 -> 0 | Y14: =$P14*Assumptions!$F$18 -> 0 | Z14: =$P14*Assumptions!$G$18 -> 115
B15: 2033 refresh 100/15/5/5 | C15: =Assumptions!$C$5 -> 100 | J15: =$C15*Assumptions!$C$17 -> 100 | K15: =$C15*Assumptions!$D$17 -> 15 | L15: =$C15*Assumptions!$E$17 -> 5 | M15: =$C15*Assumptions!$G$17 -> 125 | O15: 2033 refresh 50/50 at 115 | P15: =Assumptions!$C$11*Assumptions!$C$5*Assumptions!$C$9 -> 57.5 | W15: =$P15*Assumptions!$C$18 -> 57.5 | X15: =$P15*Assumptions!$D$18 -> 57.5 | Y15: =$P15*Assumptions!$E$18 -> 0 | Z15: =$P15*Assumptions!$G$18 -> 115
B16: 2034 refresh 100/15/5/5 | C16: =Assumptions!$C$5 -> 100 | K16: =$C16*Assumptions!$C$17 -> 100 | L16: =$C16*Assumptions!$D$17 -> 15 | M16: =$C16*Assumptions!$G$17 -> 125 | O16: 2034 refresh 50/50 at 115 | P16: =Assumptions!$C$11*Assumptions!$C$5*Assumptions!$C$9 -> 57.5 | X16: =$P16*Assumptions!$C$18 -> 57.5 | Y16: =$P16*Assumptions!$D$18 -> 57.5 | Z16: =$P16*Assumptions!$G$18 -> 115
B17: 2035 refresh 100/15/5/5 | C17: =Assumptions!$C$5 -> 100 | L17: =$C17*Assumptions!$C$17 -> 100 | M17: =$C17*Assumptions!$G$17 -> 125 | O17: 2035 refresh 50/50 at 115 | P17: =Assumptions!$C$11*Assumptions!$C$5*Assumptions!$C$9 -> 57.5 | Y17: =$P17*Assumptions!$C$18 -> 57.5 | Z17: =$P17*Assumptions!$G$18 -> 115
B18: Total annual vest | C18: Total | D18: =D8+SUM(D9:D17) -> 100 | E18: =E8+SUM(E9:E17) -> 115 | F18: =F8+SUM(F9:F17) -> 120 | G18: =G8+SUM(G9:G17) -> 125 | H18: =H8+SUM(H9:H17) -> 125 | I18: =I8+SUM(I9:I17) -> 125 | J18: =J8+SUM(J9:J17) -> 125 | K18: =K8+SUM(K9:K17) -> 125 | L18: =L8+SUM(L9:L17) -> 125 | M18: =SUM(M9:M17) -> 1125 | O18: Total annual vest | P18: Total | Q18: =Q8+SUM(Q9:Q17) -> 115 | R18: =R8+SUM(R9:R17) -> 115 | S18: =S8+SUM(S9:S17) -> 115 | T18: =T8+SUM(T9:T17) -> 115 | U18: =U8+SUM(U9:U17) -> 115 | V18: =V8+SUM(V9:V17) -> 115 | W18: =W8+SUM(W9:W17) -> 115 | X18: =X8+SUM(X9:X17) -> 115 | Y18: =Y8+SUM(Y9:Y17) -> 115 | Z18: =SUM(Z9:Z17) -> 1092.5
B19: % of steady-state ceiling | D19: =D18/D7 -> 0.8 | E19: =E18/E7 -> 0.92 | F19: =F18/F7 -> 0.96 | G19: =G18/G7 -> 1 | H19: =H18/H7 -> 1 | I19: =I18/I7 -> 1 | J19: =J18/J7 -> 1 | K19: =K18/K7 -> 1 | L19: =L18/L7 -> 1 | O19: % of steady-state ceiling | Q19: =Q18/Q7 -> 0.92 | R19: =R18/R7 -> 0.92 | S19: =S18/S7 -> 0.92 | T19: =T18/T7 -> 0.92 | U19: =U18/U7 -> 0.92 | V19: =V18/V7 -> 0.92 | W19: =W18/W7 -> 0.92 | X19: =X18/X7 -> 0.92 | Y19: =Y18/Y7 -> 0.92
B20: Change vs prior year | D20: =D18-Assumptions!$C$5 -> 0 | E20: =E18-D18 -> 15 | F20: =F18-E18 -> 5 | G20: =G18-F18 -> 5 | H20: =H18-G18 -> 0 | I20: =I18-H18 -> 0 | J20: =J18-I18 -> 0 | K20: =K18-J18 -> 0 | L20: =L18-K18 -> 0 | O20: Change vs prior year | Q20: =Q18-Assumptions!$C$5 -> 15 | R20: =R18-Q18 -> 0 | S20: =S18-R18 -> 0 | T20: =T18-S18 -> 0 | U20: =U18-T18 -> 0 | V20: =V18-U18 -> 0 | W20: =W18-V18 -> 0 | X20: =X18-W18 -> 0 | Y20: =Y18-X18 -> 0
B24: Persona B hired 2026, 0 of target vesting in the transition year transition year 2030
B25: Option 1 100/15/5/5 | C25: Sizing | D25: 2027 | E25: 2028 | F25: 2029 | G25: 2030 | H25: 2031 | I25: 2032 | J25: 2033 | K25: 2034 | L25: 2035 | M25: Face | O25: Option 2 100/50 and 50/50 | P25: Sizing | Q25: 2027 | R25: 2028 | S25: 2029 | T25: 2030 | U25: 2031 | V25: 2032 | W25: 2033 | X25: 2034 | Y25: 2035 | Z25: Face
B26: Gap target (used only in T and promo years) | D26: =Assumptions!$C$5*Assumptions!$C$6 -> 125 | E26: =Assumptions!$C$5*Assumptions!$C$6 -> 125 | F26: =Assumptions!$C$5*Assumptions!$C$6 -> 125 | G26: =Assumptions!$C$5*Assumptions!$C$6 -> 125 | H26: =Assumptions!$C$5*Assumptions!$C$6 -> 125 | I26: =Assumptions!$C$5*Assumptions!$C$6 -> 125 | J26: =Assumptions!$C$5*Assumptions!$C$6 -> 125 | K26: =Assumptions!$C$5*Assumptions!$C$6 -> 125 | L26: =Assumptions!$C$5*Assumptions!$C$6 -> 125 | O26: Gap target (used only in T and promo years) | Q26: =Assumptions!$C$5*Assumptions!$C$6 -> 125 | R26: =Assumptions!$C$5*Assumptions!$C$6 -> 125 | S26: =Assumptions!$C$5*Assumptions!$C$6 -> 125 | T26: =Assumptions!$C$5*Assumptions!$C$6 -> 125 | U26: =Assumptions!$C$5*Assumptions!$C$6 -> 125 | V26: =Assumptions!$C$5*Assumptions!$C$6 -> 125 | W26: =Assumptions!$C$5*Assumptions!$C$6 -> 125 | X26: =Assumptions!$C$5*Assumptions!$C$6 -> 125 | Y26: =Assumptions!$C$5*Assumptions!$C$6 -> 125
B27: Legacy scheduled vest | D27: 100 | E27: 100 | F27: 100 | G27: 0 | H27: 0 | I27: 0 | J27: 0 | K27: 0 | L27: 0 | O27: Legacy scheduled vest | Q27: 100 | R27: 100 | S27: 100 | T27: 0 | U27: 0 | V27: 0 | W27: 0 | X27: 0 | Y27: 0
B28: 2027 pre-transition top-up | C28: =MAX(Assumptions!$C$5*Assumptions!$C$12,D26-(D27)) -> 25 | D28: =$C28*Assumptions!$C$23 -> 25 | E28: =$C28*Assumptions!$D$23 -> 3.75 | F28: =$C28*Assumptions!$E$23 -> 1.25 | G28: =$C28*Assumptions!$F$23 -> 1.25 | M28: =$C28*Assumptions!$G$23 -> 31.25 | O28: 2027 pre-transition top-up (1 year) | P28: =MAX(Assumptions!$C$5*Assumptions!$C$12,Q26-(Q27)) -> 25 | Q28: =$P28*Assumptions!$C$21 -> 25 | R28: =$P28*Assumptions!$D$21 -> 0 | S28: =$P28*Assumptions!$E$21 -> 0 | T28: =$P28*Assumptions!$F$21 -> 0 | Z28: =$P28*Assumptions!$G$21 -> 25
B29: 2028 pre-transition top-up | C29: =MAX(Assumptions!$C$5*Assumptions!$C$12,E26-(E27)) -> 25 | E29: =$C29*Assumptions!$C$23 -> 25 | F29: =$C29*Assumptions!$D$23 -> 3.75 | G29: =$C29*Assumptions!$E$23 -> 1.25 | H29: =$C29*Assumptions!$F$23 -> 1.25 | M29: =$C29*Assumptions!$G$23 -> 31.25 | O29: 2028 pre-transition top-up (1 year) | P29: =MAX(Assumptions!$C$5*Assumptions!$C$12,R26-(R27)) -> 25 | R29: =$P29*Assumptions!$C$21 -> 25 | S29: =$P29*Assumptions!$D$21 -> 0 | T29: =$P29*Assumptions!$E$21 -> 0 | U29: =$P29*Assumptions!$F$21 -> 0 | Z29: =$P29*Assumptions!$G$21 -> 25
B30: 2029 pre-transition top-up | C30: =MAX(Assumptions!$C$5*Assumptions!$C$12,F26-(F27)) -> 25 | F30: =$C30*Assumptions!$C$23 -> 25 | G30: =$C30*Assumptions!$D$23 -> 3.75 | H30: =$C30*Assumptions!$E$23 -> 1.25 | I30: =$C30*Assumptions!$F$23 -> 1.25 | M30: =$C30*Assumptions!$G$23 -> 31.25 | O30: 2029 pre-transition top-up (1 year) | P30: =MAX(Assumptions!$C$5*Assumptions!$C$12,S26-(S27)) -> 25 | S30: =$P30*Assumptions!$C$21 -> 25 | T30: =$P30*Assumptions!$D$21 -> 0 | U30: =$P30*Assumptions!$E$21 -> 0 | V30: =$P30*Assumptions!$F$21 -> 0 | Z30: =$P30*Assumptions!$G$21 -> 25
B31: 2030 transition Grant 1 (gap on legacy) | C31: =MAX(Assumptions!$C$5*Assumptions!$C$12,G26-(G27)) -> 125 | G31: =$C31*Assumptions!$C$21 -> 125 | H31: =$C31*Assumptions!$D$21 -> 0 | I31: =$C31*Assumptions!$E$21 -> 0 | J31: =$C31*Assumptions!$F$21 -> 0 | M31: =$C31*Assumptions!$G$21 -> 125 | O31: 2030 transition 100/50 at 125 | P31: =Assumptions!$C$5*Assumptions!$C$6 -> 125 | T31: =$P31*Assumptions!$C$19 -> 125 | U31: =$P31*Assumptions!$D$19 -> 62.5 | V31: =$P31*Assumptions!$E$19 -> 0 | W31: =$P31*Assumptions!$F$19 -> 0 | Z31: =$P31*Assumptions!$G$19 -> 187.5
B32: 2030 transition Grant 2 tail 0/25/10/5 | C32: =Assumptions!$C$5 -> 100 | G32: =$C32*Assumptions!$C$22 -> 0 | H32: =$C32*Assumptions!$D$22 -> 25 | I32: =$C32*Assumptions!$E$22 -> 10 | J32: =$C32*Assumptions!$F$22 -> 5 | M32: =$C32*Assumptions!$G$22 -> 40 | O32: 2031 refresh 50/50 | P32: =Assumptions!$C$11*Assumptions!$C$5*Assumptions!$C$6 -> 62.5 | U32: =$P32*Assumptions!$C$18 -> 62.5 | V32: =$P32*Assumptions!$D$18 -> 62.5 | W32: =$P32*Assumptions!$E$18 -> 0 | X32: =$P32*Assumptions!$F$18 -> 0 | Z32: =$P32*Assumptions!$G$18 -> 125
B33: 2031 refresh 100/15/5/5 | C33: =Assumptions!$C$5 -> 100 | H33: =$C33*Assumptions!$C$17 -> 100 | I33: =$C33*Assumptions!$D$17 -> 15 | J33: =$C33*Assumptions!$E$17 -> 5 | K33: =$C33*Assumptions!$F$17 -> 5 | M33: =$C33*Assumptions!$G$17 -> 125 | O33: 2032 refresh 50/50 | P33: =Assumptions!$C$11*Assumptions!$C$5*Assumptions!$C$6 -> 62.5 | V33: =$P33*Assumptions!$C$18 -> 62.5 | W33: =$P33*Assumptions!$D$18 -> 62.5 | X33: =$P33*Assumptions!$E$18 -> 0 | Y33: =$P33*Assumptions!$F$18 -> 0 | Z33: =$P33*Assumptions!$G$18 -> 125
B34: 2032 refresh 100/15/5/5 | C34: =Assumptions!$C$5 -> 100 | I34: =$C34*Assumptions!$C$17 -> 100 | J34: =$C34*Assumptions!$D$17 -> 15 | K34: =$C34*Assumptions!$E$17 -> 5 | L34: =$C34*Assumptions!$F$17 -> 5 | M34: =$C34*Assumptions!$G$17 -> 125 | O34: 2033 refresh 50/50 | P34: =Assumptions!$C$11*Assumptions!$C$5*Assumptions!$C$6 -> 62.5 | W34: =$P34*Assumptions!$C$18 -> 62.5 | X34: =$P34*Assumptions!$D$18 -> 62.5 | Y34: =$P34*Assumptions!$E$18 -> 0 | Z34: =$P34*Assumptions!$G$18 -> 125
B35: 2033 refresh 100/15/5/5 | C35: =Assumptions!$C$5 -> 100 | J35: =$C35*Assumptions!$C$17 -> 100 | K35: =$C35*Assumptions!$D$17 -> 15 | L35: =$C35*Assumptions!$E$17 -> 5 | M35: =$C35*Assumptions!$G$17 -> 125 | O35: 2034 refresh 50/50 | P35: =Assumptions!$C$11*Assumptions!$C$5*Assumptions!$C$6 -> 62.5 | X35: =$P35*Assumptions!$C$18 -> 62.5 | Y35: =$P35*Assumptions!$D$18 -> 62.5 | Z35: =$P35*Assumptions!$G$18 -> 125
B36: 2034 refresh 100/15/5/5 | C36: =Assumptions!$C$5 -> 100 | K36: =$C36*Assumptions!$C$17 -> 100 | L36: =$C36*Assumptions!$D$17 -> 15 | M36: =$C36*Assumptions!$G$17 -> 125 | O36: 2035 refresh 50/50 | P36: =Assumptions!$C$11*Assumptions!$C$5*Assumptions!$C$6 -> 62.5 | Y36: =$P36*Assumptions!$C$18 -> 62.5 | Z36: =$P36*Assumptions!$G$18 -> 125
B37: 2035 refresh 100/15/5/5 | C37: =Assumptions!$C$5 -> 100 | L37: =$C37*Assumptions!$C$17 -> 100 | M37: =$C37*Assumptions!$G$17 -> 125 | O37: Total annual vest | P37: Total | Q37: =Q27+SUM(Q28:Q36) -> 125 | R37: =R27+SUM(R28:R36) -> 125 | S37: =S27+SUM(S28:S36) -> 125 | T37: =T27+SUM(T28:T36) -> 125 | U37: =U27+SUM(U28:U36) -> 125 | V37: =V27+SUM(V28:V36) -> 125 | W37: =W27+SUM(W28:W36) -> 125 | X37: =X27+SUM(X28:X36) -> 125 | Y37: =Y27+SUM(Y28:Y36) -> 125 | Z37: =SUM(Z28:Z36) -> 887.5
B38: Total annual vest | C38: Total | D38: =D27+SUM(D28:D37) -> 125 | E38: =E27+SUM(E28:E37) -> 128.75 | F38: =F27+SUM(F28:F37) -> 130 | G38: =G27+SUM(G28:G37) -> 131.25 | H38: =H27+SUM(H28:H37) -> 127.5 | I38: =I27+SUM(I28:I37) -> 126.25 | J38: =J27+SUM(J28:J37) -> 125 | K38: =K27+SUM(K28:K37) -> 125 | L38: =L27+SUM(L28:L37) -> 125 | M38: =SUM(M28:M37) -> 883.75 | O38: % of steady-state ceiling | Q38: =Q37/Q26 -> 1 | R38: =R37/R26 -> 1 | S38: =S37/S26 -> 1 | T38: =T37/T26 -> 1 | U38: =U37/U26 -> 1 | V38: =V37/V26 -> 1 | W38: =W37/W26 -> 1 | X38: =X37/X26 -> 1 | Y38: =Y37/Y26 -> 1
B39: % of steady-state ceiling | D39: =D38/D26 -> 1 | E39: =E38/E26 -> 1.03 | F39: =F38/F26 -> 1.04 | G39: =G38/G26 -> 1.05 | H39: =H38/H26 -> 1.02 | I39: =I38/I26 -> 1.01 | J39: =J38/J26 -> 1 | K39: =K38/K26 -> 1 | L39: =L38/L26 -> 1 | O39: Change vs prior year | Q39: =Q37-Assumptions!$C$5 -> 25 | R39: =R37-Q37 -> 0 | S39: =S37-R37 -> 0 | T39: =T37-S37 -> 0 | U39: =U37-T37 -> 0 | V39: =V37-U37 -> 0 | W39: =W37-V37 -> 0 | X39: =X37-W37 -> 0 | Y39: =Y37-X37 -> 0
B40: Change vs prior year | D40: =D38-Assumptions!$C$5 -> 25 | E40: =E38-D38 -> 3.75 | F40: =F38-E38 -> 1.25 | G40: =G38-F38 -> 1.25 | H40: =H38-G38 -> -3.75 | I40: =I38-H38 -> -1.25 | J40: =J38-I38 -> -1.25 | K40: =K38-J38 -> 0 | L40: =L38-K38 -> 0
B44: Persona C hired 2026, 25 of target vesting in the transition year transition year 2030
B45: Option 1 100/15/5/5 | C45: Sizing | D45: 2027 | E45: 2028 | F45: 2029 | G45: 2030 | H45: 2031 | I45: 2032 | J45: 2033 | K45: 2034 | L45: 2035 | M45: Face | O45: Option 2 100/50 and 50/50 | P45: Sizing | Q45: 2027 | R45: 2028 | S45: 2029 | T45: 2030 | U45: 2031 | V45: 2032 | W45: 2033 | X45: 2034 | Y45: 2035 | Z45: Face
B46: Gap target (used only in T and promo years) | D46: =Assumptions!$C$5*Assumptions!$C$6 -> 125 | E46: =Assumptions!$C$5*Assumptions!$C$6 -> 125 | F46: =Assumptions!$C$5*Assumptions!$C$6 -> 125 | G46: =Assumptions!$C$5*Assumptions!$C$6 -> 125 | H46: =Assumptions!$C$5*Assumptions!$C$6 -> 125 | I46: =Assumptions!$C$5*Assumptions!$C$6 -> 125 | J46: =Assumptions!$C$5*Assumptions!$C$6 -> 125 | K46: =Assumptions!$C$5*Assumptions!$C$6 -> 125 | L46: =Assumptions!$C$5*Assumptions!$C$6 -> 125 | O46: Gap target (used only in T and promo years) | Q46: =Assumptions!$C$5*Assumptions!$C$6 -> 125 | R46: =Assumptions!$C$5*Assumptions!$C$6 -> 125 | S46: =Assumptions!$C$5*Assumptions!$C$6 -> 125 | T46: =Assumptions!$C$5*Assumptions!$C$6 -> 125 | U46: =Assumptions!$C$5*Assumptions!$C$6 -> 125 | V46: =Assumptions!$C$5*Assumptions!$C$6 -> 125 | W46: =Assumptions!$C$5*Assumptions!$C$6 -> 125 | X46: =Assumptions!$C$5*Assumptions!$C$6 -> 125 | Y46: =Assumptions!$C$5*Assumptions!$C$6 -> 125
B47: Legacy scheduled vest | D47: 100 | E47: 100 | F47: 100 | G47: 25 | H47: 0 | I47: 0 | J47: 0 | K47: 0 | L47: 0 | O47: Legacy scheduled vest | Q47: 100 | R47: 100 | S47: 100 | T47: 25 | U47: 0 | V47: 0 | W47: 0 | X47: 0 | Y47: 0
B48: 2027 pre-transition top-up | C48: =MAX(Assumptions!$C$5*Assumptions!$C$12,D46-(D47)) -> 25 | D48: =$C48*Assumptions!$C$23 -> 25 | E48: =$C48*Assumptions!$D$23 -> 3.75 | F48: =$C48*Assumptions!$E$23 -> 1.25 | G48: =$C48*Assumptions!$F$23 -> 1.25 | M48: =$C48*Assumptions!$G$23 -> 31.25 | O48: 2027 pre-transition top-up (1 year) | P48: =MAX(Assumptions!$C$5*Assumptions!$C$12,Q46-(Q47)) -> 25 | Q48: =$P48*Assumptions!$C$21 -> 25 | R48: =$P48*Assumptions!$D$21 -> 0 | S48: =$P48*Assumptions!$E$21 -> 0 | T48: =$P48*Assumptions!$F$21 -> 0 | Z48: =$P48*Assumptions!$G$21 -> 25
...

Sheet Promo in T
B2: Scenario: Promo in T
B3: Grants in rows, years in columns. Option 1 left, Option 2 right. Index: annual LTI target = 100.
B5: Persona A new hire 2027, no legacy grant transition year 2027
B6: Option 1 100/15/5/5 | C6: Sizing | D6: 2027 | E6: 2028 | F6: 2029 | G6: 2030 | H6: 2031 | I6: 2032 | J6: 2033 | K6: 2034 | L6: 2035 | M6: Face | O6: Option 2 100/50 and 50/50 | P6: Sizing | Q6: 2027 | R6: 2028 | S6: 2029 | T6: 2030 | U6: 2031 | V6: 2032 | W6: 2033 | X6: 2034 | Y6: 2035 | Z6: Face
B7: Gap target (used only in T and promo years) | D7: =Assumptions!$C$5*Assumptions!$C$6 -> 125 | E7: =Assumptions!$C$5*Assumptions!$C$6 -> 125 | F7: =Assumptions!$C$5*Assumptions!$C$8 -> 200 | G7: =Assumptions!$C$5*Assumptions!$C$6 -> 125 | H7: =Assumptions!$C$5*Assumptions!$C$6 -> 125 | I7: =Assumptions!$C$5*Assumptions!$C$6 -> 125 | J7: =Assumptions!$C$5*Assumptions!$C$6 -> 125 | K7: =Assumptions!$C$5*Assumptions!$C$6 -> 125 | L7: =Assumptions!$C$5*Assumptions!$C$6 -> 125 | O7: Gap target (used only in T and promo years) | Q7: =Assumptions!$C$5*Assumptions!$C$6 -> 125 | R7: =Assumptions!$C$5*Assumptions!$C$6 -> 125 | S7: =Assumptions!$C$10 -> 230 | T7: =Assumptions!$C$5*Assumptions!$C$6 -> 125 | U7: =Assumptions!$C$5*Assumptions!$C$6 -> 125 | V7: =Assumptions!$C$5*Assumptions!$C$6 -> 125 | W7: =Assumptions!$C$5*Assumptions!$C$6 -> 125 | X7: =Assumptions!$C$5*Assumptions!$C$6 -> 125 | Y7: =Assumptions!$C$5*Assumptions!$C$6 -> 125
B8: Legacy scheduled vest | D8: 0 | E8: 0 | F8: 0 | G8: 0 | H8: 0 | I8: 0 | J8: 0 | K8: 0 | L8: 0 | O8: Legacy scheduled vest | Q8: 0 | R8: 0 | S8: 0 | T8: 0 | U8: 0 | V8: 0 | W8: 0 | X8: 0 | Y8: 0
B9: 2027 new hire 100/15/5/5 | C9: =Assumptions!$C$5 -> 100 | D9: =$C9*Assumptions!$C$17 -> 100 | E9: =$C9*Assumptions!$D$17 -> 15 | F9: =$C9*Assumptions!$E$17 -> 5 | G9: =$C9*Assumptions!$F$17 -> 5 | M9: =$C9*Assumptions!$G$17 -> 125 | O9: 2027 new hire 100/50 at 1.15x | P9: =Assumptions!$C$5*Assumptions!$C$9 -> 115 | Q9: =$P9*Assumptions!$C$19 -> 115 | R9: =$P9*Assumptions!$D$19 -> 57.5 | S9: =$P9*Assumptions!$E$19 -> 0 | T9: =$P9*Assumptions!$F$19 -> 0 | Z9: =$P9*Assumptions!$G$19 -> 172.5
B10: 2028 refresh 100/15/5/5 | C10: =Assumptions!$C$5 -> 100 | E10: =$C10*Assumptions!$C$17 -> 100 | F10: =$C10*Assumptions!$D$17 -> 15 | G10: =$C10*Assumptions!$E$17 -> 5 | H10: =$C10*Assumptions!$F$17 -> 5 | M10: =$C10*Assumptions!$G$17 -> 125 | O10: 2028 refresh 50/50 at 115 | P10: =Assumptions!$C$11*Assumptions!$C$5*Assumptions!$C$9 -> 57.5 | R10: =$P10*Assumptions!$C$18 -> 57.5 | S10: =$P10*Assumptions!$D$18 -> 57.5 | T10: =$P10*Assumptions!$E$18 -> 0 | U10: =$P10*Assumptions!$F$18 -> 0 | Z10: =$P10*Assumptions!$G$18 -> 115
B11: 2029 promo 100/15/5/5 | C11: =MAX(0,F7-(F8)) -> 200 | F11: =$C11*Assumptions!$C$17 -> 200 | G11: =$C11*Assumptions!$D$17 -> 30 | H11: =$C11*Assumptions!$E$17 -> 10 | I11: =$C11*Assumptions!$F$17 -> 10 | M11: =$C11*Assumptions!$G$17 -> 250 | O11: 2029 promo one-year (gap to 230) | P11: =MAX(0,S7-(S8+SUM(S9:S10))) -> 172.5 | S11: =$P11*Assumptions!$C$21 -> 172.5 | T11: =$P11*Assumptions!$D$21 -> 0 | U11: =$P11*Assumptions!$E$21 -> 0 | V11: =$P11*Assumptions!$F$21 -> 0 | Z11: =$P11*Assumptions!$G$21 -> 172.5
B12: 2030 refresh 200/30/10/10 | C12: =Assumptions!$C$5*Assumptions!$C$8 -> 200 | G12: =$C12*Assumptions!$C$17 -> 200 | H12: =$C12*Assumptions!$D$17 -> 30 | I12: =$C12*Assumptions!$E$17 -> 10 | J12: =$C12*Assumptions!$F$17 -> 10 | M12: =$C12*Assumptions!$G$17 -> 250 | O12: 2030 post-promo 100/50 at 230 | P12: =Assumptions!$C$10 -> 230 | T12: =$P12*Assumptions!$C$19 -> 230 | U12: =$P12*Assumptions!$D$19 -> 115 | V12: =$P12*Assumptions!$E$19 -> 0 | W12: =$P12*Assumptions!$F$19 -> 0 | Z12: =$P12*Assumptions!$G$19 -> 345
B13: 2031 refresh 200/30/10/10 | C13: =Assumptions!$C$5*Assumptions!$C$8 -> 200 | H13: =$C13*Assumptions!$C$17 -> 200 | I13: =$C13*Assumptions!$D$17 -> 30 | J13: =$C13*Assumptions!$E$17 -> 10 | K13: =$C13*Assumptions!$F$17 -> 10 | M13: =$C13*Assumptions!$G$17 -> 250 | O13: 2031 refresh 50/50 at 230 | P13: =Assumptions!$C$11*Assumptions!$C$10 -> 115 | U13: =$P13*Assumptions!$C$18 -> 115 | V13: =$P13*Assumptions!$D$18 -> 115 | W13: =$P13*Assumptions!$E$18 -> 0 | X13: =$P13*Assumptions!$F$18 -> 0 | Z13: =$P13*Assumptions!$G$18 -> 230
B14: 2032 refresh 200/30/10/10 | C14: =Assumptions!$C$5*Assumptions!$C$8 -> 200 | I14: =$C14*Assumptions!$C$17 -> 200 | J14: =$C14*Assumptions!$D$17 -> 30 | K14: =$C14*Assumptions!$E$17 -> 10 | L14: =$C14*Assumptions!$F$17 -> 10 | M14: =$C14*Assumptions!$G$17 -> 250 | O14: 2032 refresh 50/50 at 230 | P14: =Assumptions!$C$11*Assumptions!$C$10 -> 115 | V14: =$P14*Assumptions!$C$18 -> 115 | W14: =$P14*Assumptions!$D$18 -> 115 | X14: =$P14*Assumptions!$E$18 -> 0 | Y14: =$P14*Assumptions!$F$18 -> 0 | Z14: =$P14*Assumptions!$G$18 -> 230
B15: 2033 refresh 200/30/10/10 | C15: =Assumptions!$C$5*Assumptions!$C$8 -> 200 | J15: =$C15*Assumptions!$C$17 -> 200 | K15: =$C15*Assumptions!$D$17 -> 30 | L15: =$C15*Assumptions!$E$17 -> 10 | M15: =$C15*Assumptions!$G$17 -> 250 | O15: 2033 refresh 50/50 at 230 | P15: =Assumptions!$C$11*Assumptions!$C$10 -> 115 | W15: =$P15*Assumptions!$C$18 -> 115 | X15: =$P15*Assumptions!$D$18 -> 115 | Y15: =$P15*Assumptions!$E$18 -> 0 | Z15: =$P15*Assumptions!$G$18 -> 230
B16: 2034 refresh 200/30/10/10 | C16: =Assumptions!$C$5*Assumptions!$C$8 -> 200 | K16: =$C16*Assumptions!$C$17 -> 200 | L16: =$C16*Assumptions!$D$17 -> 30 | M16: =$C16*Assumptions!$G$17 -> 250 | O16: 2034 refresh 50/50 at 230 | P16: =Assumptions!$C$11*Assumptions!$C$10 -> 115 | X16: =$P16*Assumptions!$C$18 -> 115 | Y16: =$P16*Assumptions!$D$18 -> 115 | Z16: =$P16*Assumptions!$G$18 -> 230
B17: 2035 refresh 200/30/10/10 | C17: =Assumptions!$C$5*Assumptions!$C$8 -> 200 | L17: =$C17*Assumptions!$C$17 -> 200 | M17: =$C17*Assumptions!$G$17 -> 250 | O17: 2035 refresh 50/50 at 230 | P17: =Assumptions!$C$11*Assumptions!$C$10 -> 115 | Y17: =$P17*Assumptions!$C$18 -> 115 | Z17: =$P17*Assumptions!$G$18 -> 230
B18: Total annual vest | C18: Total | D18: =D8+SUM(D9:D17) -> 100 | E18: =E8+SUM(E9:E17) -> 115 | F18: =F8+SUM(F9:F17) -> 220 | G18: =G8+SUM(G9:G17) -> 240 | H18: =H8+SUM(H9:H17) -> 245 | I18: =I8+SUM(I9:I17) -> 250 | J18: =J8+SUM(J9:J17) -> 250 | K18: =K8+SUM(K9:K17) -> 250 | L18: =L8+SUM(L9:L17) -> 250 | M18: =SUM(M9:M17) -> 2000 | O18: Total annual vest | P18: Total | Q18: =Q8+SUM(Q9:Q17) -> 115 | R18: =R8+SUM(R9:R17) -> 115 | S18: =S8+SUM(S9:S17) -> 230 | T18: =T8+SUM(T9:T17) -> 230 | U18: =U8+SUM(U9:U17) -> 230 | V18: =V8+SUM(V9:V17) -> 230 | W18: =W8+SUM(W9:W17) -> 230 | X18: =X8+SUM(X9:X17) -> 230 | Y18: =Y8+SUM(Y9:Y17) -> 230 | Z18: =SUM(Z9:Z17) -> 1955
B19: % of steady-state ceiling | D19: =D18/D7 -> 0.8 | E19: =E18/E7 -> 0.92 | F19: =F18/F7 -> 1.1 | G19: =G18/G7 -> 1.92 | H19: =H18/H7 -> 1.96 | I19: =I18/I7 -> 2 | J19: =J18/J7 -> 2 | K19: =K18/K7 -> 2 | L19: =L18/L7 -> 2 | O19: % of steady-state ceiling | Q19: =Q18/Q7 -> 0.92 | R19: =R18/R7 -> 0.92 | S19: =S18/S7 -> 1 | T19: =T18/T7 -> 1.84 | U19: =U18/U7 -> 1.84 | V19: =V18/V7 -> 1.84 | W19: =W18/W7 -> 1.84 | X19: =X18/X7 -> 1.84 | Y19: =Y18/Y7 -> 1.84
B20: Change vs prior year | D20: =D18-Assumptions!$C$5 -> 0 | E20: =E18-D18 -> 15 | F20: =F18-E18 -> 105 | G20: =G18-F18 -> 20 | H20: =H18-G18 -> 5 | I20: =I18-H18 -> 5 | J20: =J18-I18 -> 0 | K20: =K18-J18 -> 0 | L20: =L18-K18 -> 0 | O20: Change vs prior year | Q20: =Q18-Assumptions!$C$5 -> 15 | R20: =R18-Q18 -> 0 | S20: =S18-R18 -> 115 | T20: =T18-S18 -> 0 | U20: =U18-T18 -> 0 | V20: =V18-U18 -> 0 | W20: =W18-V18 -> 0 | X20: =X18-W18 -> 0 | Y20: =Y18-X18 -> 0
B24: Persona B hired 2026, 0 of target vesting in the transition year transition year 2030
B25: Option 1 100/15/5/5 | C25: Sizing | D25: 2027 | E25: 2028 | F25: 2029 | G25: 2030 | H25: 2031 | I25: 2032 | J25: 2033 | K25: 2034 | L25: 2035 | M25: Face | O25: Option 2 100/50 and 50/50 | P25: Sizing | Q25: 2027 | R25: 2028 | S25: 2029 | T25: 2030 | U25: 2031 | V25: 2032 | W25: 2033 | X25: 2034 | Y25: 2035 | Z25: Face
B26: Gap target (used only in T and promo years) | D26: =Assumptions!$C$5*Assumptions!$C$6 -> 125 | E26: =Assumptions!$C$5*Assumptions!$C$6 -> 125 | F26: =Assumptions!$C$5*Assumptions!$C$6 -> 125 | G26: =Assumptions!$C$5*Assumptions!$C$8 -> 200 | H26: =Assumptions!$C$5*Assumptions!$C$6 -> 125 | I26: =Assumptions!$C$5*Assumptions!$C$6 -> 125 | J26: =Assumptions!$C$5*Assumptions!$C$6 -> 125 | K26: =Assumptions!$C$5*Assumptions!$C$6 -> 125 | L26: =Assumptions!$C$5*Assumptions!$C$6 -> 125 | O26: Gap target (used only in T and promo years) | Q26: =Assumptions!$C$5*Assumptions!$C$6 -> 125 | R26: =Assumptions!$C$5*Assumptions!$C$6 -> 125 | S26: =Assumptions!$C$5*Assumptions!$C$6 -> 125 | T26: =Assumptions!$C$10 -> 230 | U26: =Assumptions!$C$5*Assumptions!$C$6 -> 125 | V26: =Assumptions!$C$5*Assumptions!$C$6 -> 125 | W26: =Assumptions!$C$5*Assumptions!$C$6 -> 125 | X26: =Assumptions!$C$5*Assumptions!$C$6 -> 125 | Y26: =Assumptions!$C$5*Assumptions!$C$6 -> 125
B27: Legacy scheduled vest | D27: 100 | E27: 100 | F27: 100 | G27: 0 | H27: 0 | I27: 0 | J27: 0 | K27: 0 | L27: 0 | O27: Legacy scheduled vest | Q27: 100 | R27: 100 | S27: 100 | T27: 0 | U27: 0 | V27: 0 | W27: 0 | X27: 0 | Y27: 0
B28: 2027 pre-transition top-up | C28: =MAX(Assumptions!$C$5*Assumptions!$C$12,D26-(D27)) -> 25 | D28: =$C28*Assumptions!$C$23 -> 25 | E28: =$C28*Assumptions!$D$23 -> 3.75 | F28: =$C28*Assumptions!$E$23 -> 1.25 | G28: =$C28*Assumptions!$F$23 -> 1.25 | M28: =$C28*Assumptions!$G$23 -> 31.25 | O28: 2027 pre-transition top-up (1 year) | P28: =MAX(Assumptions!$C$5*Assumptions!$C$12,Q26-(Q27)) -> 25 | Q28: =$P28*Assumptions!$C$21 -> 25 | R28: =$P28*Assumptions!$D$21 -> 0 | S28: =$P28*Assumptions!$E$21 -> 0 | T28: =$P28*Assumptions!$F$21 -> 0 | Z28: =$P28*Assumptions!$G$21 -> 25
B29: 2028 pre-transition top-up | C29: =MAX(Assumptions!$C$5*Assumptions!$C$12,E26-(E27)) -> 25 | E29: =$C29*Assumptions!$C$23 -> 25 | F29: =$C29*Assumptions!$D$23 -> 3.75 | G29: =$C29*Assumptions!$E$23 -> 1.25 | H29: =$C29*Assumptions!$F$23 -> 1.25 | M29: =$C29*Assumptions!$G$23 -> 31.25 | O29: 2028 pre-transition top-up (1 year) | P29: =MAX(Assumptions!$C$5*Assumptions!$C$12,R26-(R27)) -> 25 | R29: =$P29*Assumptions!$C$21 -> 25 | S29: =$P29*Assumptions!$D$21 -> 0 | T29: =$P29*Assumptions!$E$21 -> 0 | U29: =$P29*Assumptions!$F$21 -> 0 | Z29: =$P29*Assumptions!$G$21 -> 25
B30: 2029 pre-transition top-up | C30: =MAX(Assumptions!$C$5*Assumptions!$C$12,F26-(F27)) -> 25 | F30: =$C30*Assumptions!$C$23 -> 25 | G30: =$C30*Assumptions!$D$23 -> 3.75 | H30: =$C30*Assumptions!$E$23 -> 1.25 | I30: =$C30*Assumptions!$F$23 -> 1.25 | M30: =$C30*Assumptions!$G$23 -> 31.25 | O30: 2029 pre-transition top-up (1 year) | P30: =MAX(Assumptions!$C$5*Assumptions!$C$12,S26-(S27)) -> 25 | S30: =$P30*Assumptions!$C$21 -> 25 | T30: =$P30*Assumptions!$D$21 -> 0 | U30: =$P30*Assumptions!$E$21 -> 0 | V30: =$P30*Assumptions!$F$21 -> 0 | Z30: =$P30*Assumptions!$G$21 -> 25
B31: 2030 promo grant (gap to 200) | C31: =MAX(Assumptions!$C$5*Assumptions!$C$12,G26-(G27)) -> 200 | G31: =$C31*Assumptions!$C$23 -> 200 | H31: =$C31*Assumptions!$D$23 -> 30 | I31: =$C31*Assumptions!$E$23 -> 10 | J31: =$C31*Assumptions!$F$23 -> 10 | M31: =$C31*Assumptions!$G$23 -> 250 | O31: 2030 transition 100/50 at 230 | P31: =Assumptions!$C$10 -> 230 | T31: =$P31*Assumptions!$C$19 -> 230 | U31: =$P31*Assumptions!$D$19 -> 115 | V31: =$P31*Assumptions!$E$19 -> 0 | W31: =$P31*Assumptions!$F$19 -> 0 | Z31: =$P31*Assumptions!$G$19 -> 345
B32: 2031 refresh 200/30/10/10 | C32: =Assumptions!$C$5*Assumptions!$C$8 -> 200 | H32: =$C32*Assumptions!$C$17 -> 200 | I32: =$C32*Assumptions!$D$17 -> 30 | J32: =$C32*Assumptions!$E$17 -> 10 | K32: =$C32*Assumptions!$F$17 -> 10 | M32: =$C32*Assumptions!$G$17 -> 250 | O32: 2031 refresh 50/50 at 230 | P32: =Assumptions!$C$11*Assumptions!$C$10 -> 115 | U32: =$P32*Assumptions!$C$18 -> 115 | V32: =$P32*Assumptions!$D$18 -> 115 | W32: =$P32*Assumptions!$E$18 -> 0 | X32: =$P32*Assumptions!$F$18 -> 0 | Z32: =$P32*Assumptions!$G$18 -> 230
B33: 2032 refresh 200/30/10/10 | C33: =Assumptions!$C$5*Assumptions!$C$8 -> 200 | I33: =$C33*Assumptions!$C$17 -> 200 | J33: =$C33*Assumptions!$D$17 -> 30 | K33: =$C33*Assumptions!$E$17 -> 10 | L33: =$C33*Assumptions!$F$17 -> 10 | M33: =$C33*Assumptions!$G$17 -> 250 | O33: 2032 refresh 50/50 at 230 | P33: =Assumptions!$C$11*Assumptions!$C$10 -> 115 | V33: =$P33*Assumptions!$C$18 -> 115 | W33: =$P33*Assumptions!$D$18 -> 115 | X33: =$P33*Assumptions!$E$18 -> 0 | Y33: =$P33*Assumptions!$F$18 -> 0 | Z33: =$P33*Assumptions!$G$18 -> 230
B34: 2033 refresh 200/30/10/10 | C34: =Assumptions!$C$5*Assumptions!$C$8 -> 200 | J34: =$C34*Assumptions!$C$17 -> 200 | K34: =$C34*Assumptions!$D$17 -> 30 | L34: =$C34*Assumptions!$E$17 -> 10 | M34: =$C34*Assumptions!$G$17 -> 250 | O34: 2033 refresh 50/50 at 230 | P34: =Assumptions!$C$11*Assumptions!$C$10 -> 115 | W34: =$P34*Assumptions!$C$18 -> 115 | X34: =$P34*Assumptions!$D$18 -> 115 | Y34: =$P34*Assumptions!$E$18 -> 0 | Z34: =$P34*Assumptions!$G$18 -> 230
B35: 2034 refresh 200/30/10/10 | C35: =Assumptions!$C$5*Assumptions!$C$8 -> 200 | K35: =$C35*Assumptions!$C$17 -> 200 | L35: =$C35*Assumptions!$D$17 -> 30 | M35: =$C35*Assumptions!$G$17 -> 250 | O35: 2034 refresh 50/50 at 230 | P35: =Assumptions!$C$11*Assumptions!$C$10 -> 115 | X35: =$P35*Assumptions!$C$18 -> 115 | Y35: =$P35*Assumptions!$D$18 -> 115 | Z35: =$P35*Assumptions!$G$18 -> 230
B36: 2035 refresh 200/30/10/10 | C36: =Assumptions!$C$5*Assumptions!$C$8 -> 200 | L36: =$C36*Assumptions!$C$17 -> 200 | M36: =$C36*Assumptions!$G$17 -> 250 | O36: 2035 refresh 50/50 at 230 | P36: =Assumptions!$C$11*Assumptions!$C$10 -> 115 | Y36: =$P36*Assumptions!$C$18 -> 115 | Z36: =$P36*Assumptions!$G$18 -> 230
B37: Total annual vest | C37: Total | D37: =D27+SUM(D28:D36) -> 125 | E37: =E27+SUM(E28:E36) -> 128.75 | F37: =F27+SUM(F28:F36) -> 130 | G37: =G27+SUM(G28:G36) -> 206.25 | H37: =H27+SUM(H28:H36) -> 232.5 | I37: =I27+SUM(I28:I36) -> 241.25 | J37: =J27+SUM(J28:J36) -> 250 | K37: =K27+SUM(K28:K36) -> 250 | L37: =L27+SUM(L28:L36) -> 250 | M37: =SUM(M28:M36) -> 1593.75 | O37: Total annual vest | P37: Total | Q37: =Q27+SUM(Q28:Q36) -> 125 | R37: =R27+SUM(R28:R36) -> 125 | S37: =S27+SUM(S28:S36) -> 125 | T37: =T27+SUM(T28:T36) -> 230 | U37: =U27+SUM(U28:U36) -> 230 | V37: =V27+SUM(V28:V36) -> 230 | W37: =W27+SUM(W28:W36) -> 230 | X37: =X27+SUM(X28:X36) -> 230 | Y37: =Y27+SUM(Y28:Y36) -> 230 | Z37: =SUM(Z28:Z36) -> 1570
B38: % of steady-state ceiling | D38: =D37/D26 -> 1 | E38: =E37/E26 -> 1.03 | F38: =F37/F26 -> 1.04 | G38: =G37/G26 -> 1.03125 | H38: =H37/H26 -> 1.86 | I38: =I37/I26 -> 1.93 | J38: =J37/J26 -> 2 | K38: =K37/K26 -> 2 | L38: =L37/L26 -> 2 | O38: % of steady-state ceiling | Q38: =Q37/Q26 -> 1 | R38: =R37/R26 -> 1 | S38: =S37/S26 -> 1 | T38: =T37/T26 -> 1 | U38: =U37/U26 -> 1.84 | V38: =V37/V26 -> 1.84 | W38: =W37/W26 -> 1.84 | X38: =X37/X26 -> 1.84 | Y38: =Y37/Y26 -> 1.84
B39: Change vs prior year | D39: =D37-Assumptions!$C$5 -> 25 | E39: =E37-D37 -> 3.75 | F39: =F37-E37 -> 1.25 | G39: =G37-F37 -> 76.25 | H39: =H37-G37 -> 26.25 | I39: =I37-H37 -> 8.75 | J39: =J37-I37 -> 8.75 | K39: =K37-J37 -> 0 | L39: =L37-K37 -> 0 | O39: Change vs prior year | Q39: =Q37-Assumptions!$C$5 -> 25 | R39: =R37-Q37 -> 0 | S39: =S37-R37 -> 0 | T39: =T37-S37 -> 105 | U39: =U37-T37 -> 0 | V39: =V37-U37 -> 0 | W39: =W37-V37 -> 0 | X39: =X37-W37 -> 0 | Y39: =Y37-X37 -> 0
B43: Persona C hired 2026, 25 of target vesting in the transition year transition year 2030
B44: Option 1 100/15/5/5 | C44: Sizing | D44: 2027 | E44: 2028 | F44: 2029 | G44: 2030 | H44: 2031 | I44: 2032 | J44: 2033 | K44: 2034 | L44: 2035 | M44: Face | O44: Option 2 100/50 and 50/50 | P44: Sizing | Q44: 2027 | R44: 2028 | S44: 2029 | T44: 2030 | U44: 2031 | V44: 2032 | W44: 2033 | X44: 2034 | Y44: 2035 | Z44: Face
B45: Gap target (used only in T and promo years) | D45: =Assumptions!$C$5*Assumptions!$C$6 -> 125 | E45: =Assumptions!$C$5*Assumptions!$C$6 -> 125 | F45: =Assumptions!$C$5*Assumptions!$C$6 -> 125 | G45: =Assumptions!$C$5*Assumptions!$C$8 -> 200 | H45: =Assumptions!$C$5*Assumptions!$C$6 -> 125 | I45: =Assumptions!$C$5*Assumptions!$C$6 -> 125 | J45: =Assumptions!$C$5*Assumptions!$C$6 -> 125 | K45: =Assumptions!$C$5*Assumptions!$C$6 -> 125 | L45: =Assumptions!$C$5*Assumptions!$C$6 -> 125 | O45: Gap target (used only in T and promo years) | Q45: =Assumptions!$C$5*Assumptions!$C$6 -> 125 | R45: =Assumptions!$C$5*Assumptions!$C$6 -> 125 | S45: =Assumptions!$C$5*Assumptions!$C$6 -> 125 | T45: =Assumptions!$C$10 -> 230 | U45: =Assumptions!$C$5*Assumptions!$C$6 -> 125 | V45: =Assumptions!$C$5*Assumptions!$C$6 -> 125 | W45: =Assumptions!$C$5*Assumptions!$C$6 -> 125 | X45: =Assumptions!$C$5*Assumptions!$C$6 -> 125 | Y45: =Assumptions!$C$5*Assumptions!$C$6 -> 125
B46: Legacy scheduled vest | D46: 100 | E46: 100 | F46: 100 | G46: 25 | H46: 0 | I46: 0 | J46: 0 | K46: 0 | L46: 0 | O46: Legacy scheduled vest | Q46: 100 | R46: 100 | S46: 100 | T46: 25 | U46: 0 | V46: 0 | W46: 0 | X46: 0 | Y46: 0
B47: 2027 pre-transition top-up | C47: =MAX(Assumptions!$C$5*Assumptions!$C$12,D45-(D46)) -> 25 | D47: =$C47*Assumptions!$C$23 -> 25 | E47: =$C47*Assumptions!$D$23 -> 3.75 | F47: =$C47*Assumptions!$E$23 -> 1.25 | G47: =$C47*Assumptions!$F$23 -> 1.25 | M47: =$C47*Assumptions!$G$23 -> 31.25 | O47: 2027 pre-transition top-up (1 year) | P47: =MAX(Assumptions!$C$5*Assumptions!$C$12,Q45-(Q46)) -> 25 | Q47: =$P47*Assumptions!$C$21 -> 25 | R47: =$P47*Assumptions!$D$21 -> 0 | S47: =$P47*Assumptions!$E$21 -> 0 | T47: =$P47*Assumptions!$F$21 -> 0 | Z47: =$P47*Assumptions!$G$21 -> 25
B48: 2028 pre-transition top-up | C48: =MAX(Assumptions!$C$5*Assumptions!$C$12,E45-(E46)) -> 25 | E48: =$C48*Assumptions!$C$23 -> 25 | F48: =$C48*Assumptions!$D$23 -> 3.75 | G48: =$C48*Assumptions!$E$23 -> 1.25 | H48: =$C48*Assumptions!$F$23 -> 1.25 | M48: =$C48*Assumptions!$G$23 -> 31.25 | O48: 2028 pre-transition top-up (1 year) | P48: =MAX(Assumptions!$C$5*Assumptions!$C$12,R45-(R46)) -> 25 | R48: =$P48*Assumptions!$C$21 -> 25 | S48: =$P48*Assumptions!$D$21 -> 0 | T48: =$P48*Assumptions!$E$21 -> 0 | U48: =$P48*Assumptions!$F$21 -> 0 | Z48: =$P48*Assumptions!$G$21 -> 25
...

Sheet Promo before T
B2: Scenario: Promo before T
B3: Grants in rows, years in columns. Option 1 left, Option 2 right. Index: annual LTI target = 100.
B5: Persona A new hire 2027, no legacy grant transition year 2027
B6: Not applicable. The transition year is 2027, the first year of the new programme, so there is no year before it.
B9: Persona B hired 2026, 0 of target vesting in the transition year transition year 2030
B10: Option 1 100/15/5/5 | C10: Sizing | D10: 2027 | E10: 2028 | F10: 2029 | G10: 2030 | H10: 2031 | I10: 2032 | J10: 2033 | K10: 2034 | L10: 2035 | M10: Face | O10: Option 2 100/50 and 50/50 | P10: Sizing | Q10: 2027 | R10: 2028 | S10: 2029 | T10: 2030 | U10: 2031 | V10: 2032 | W10: 2033 | X10: 2034 | Y10: 2035 | Z10: Face
B11: Gap target (used only in T and promo years) | D11: =Assumptions!$C$5*Assumptions!$C$6 -> 125 | E11: =Assumptions!$C$5*Assumptions!$C$6 -> 125 | F11: =Assumptions!$C$5*Assumptions!$C$8 -> 200 | G11: =Assumptions!$C$5*Assumptions!$C$8 -> 200 | H11: =Assumptions!$C$5*Assumptions!$C$6 -> 125 | I11: =Assumptions!$C$5*Assumptions!$C$6 -> 125 | J11: =Assumptions!$C$5*Assumptions!$C$6 -> 125 | K11: =Assumptions!$C$5*Assumptions!$C$6 -> 125 | L11: =Assumptions!$C$5*Assumptions!$C$6 -> 125 | O11: Gap target (used only in T and promo years) | Q11: =Assumptions!$C$5*Assumptions!$C$6 -> 125 | R11: =Assumptions!$C$5*Assumptions!$C$6 -> 125 | S11: =Assumptions!$C$10 -> 230 | T11: =Assumptions!$C$10 -> 230 | U11: =Assumptions!$C$5*Assumptions!$C$6 -> 125 | V11: =Assumptions!$C$5*Assumptions!$C$6 -> 125 | W11: =Assumptions!$C$5*Assumptions!$C$6 -> 125 | X11: =Assumptions!$C$5*Assumptions!$C$6 -> 125 | Y11: =Assumptions!$C$5*Assumptions!$C$6 -> 125
B12: Legacy scheduled vest | D12: 100 | E12: 100 | F12: 100 | G12: 0 | H12: 0 | I12: 0 | J12: 0 | K12: 0 | L12: 0 | O12: Legacy scheduled vest | Q12: 100 | R12: 100 | S12: 100 | T12: 0 | U12: 0 | V12: 0 | W12: 0 | X12: 0 | Y12: 0
B13: 2027 pre-transition top-up | C13: =MAX(Assumptions!$C$5*Assumptions!$C$12,D11-(D12)) -> 25 | D13: =$C13*Assumptions!$C$23 -> 25 | E13: =$C13*Assumptions!$D$23 -> 3.75 | F13: =$C13*Assumptions!$E$23 -> 1.25 | G13: =$C13*Assumptions!$F$23 -> 1.25 | M13: =$C13*Assumptions!$G$23 -> 31.25 | O13: 2027 pre-transition top-up (1 year) | P13: =MAX(Assumptions!$C$5*Assumptions!$C$12,Q11-(Q12)) -> 25 | Q13: =$P13*Assumptions!$C$21 -> 25 | R13: =$P13*Assumptions!$D$21 -> 0 | S13: =$P13*Assumptions!$E$21 -> 0 | T13: =$P13*Assumptions!$F$21 -> 0 | Z13: =$P13*Assumptions!$G$21 -> 25
B14: 2028 pre-transition top-up | C14: =MAX(Assumptions!$C$5*Assumptions!$C$12,E11-(E12)) -> 25 | E14: =$C14*Assumptions!$C$23 -> 25 | F14: =$C14*Assumptions!$D$23 -> 3.75 | G14: =$C14*Assumptions!$E$23 -> 1.25 | H14: =$C14*Assumptions!$F$23 -> 1.25 | M14: =$C14*Assumptions!$G$23 -> 31.25 | O14: 2028 pre-transition top-up (1 year) | P14: =MAX(Assumptions!$C$5*Assumptions!$C$12,R11-(R12)) -> 25 | R14: =$P14*Assumptions!$C$21 -> 25 | S14: =$P14*Assumptions!$D$21 -> 0 | T14: =$P14*Assumptions!$E$21 -> 0 | U14: =$P14*Assumptions!$F$21 -> 0 | Z14: =$P14*Assumptions!$G$21 -> 25
B15: 2029 promo grant (gap to 200) | C15: =MAX(Assumptions!$C$5*Assumptions!$C$12,F11-(F12)) -> 100 | F15: =$C15*Assumptions!$C$23 -> 100 | G15: =$C15*Assumptions!$D$23 -> 15 | H15: =$C15*Assumptions!$E$23 -> 5 | I15: =$C15*Assumptions!$F$23 -> 5 | M15: =$C15*Assumptions!$G$23 -> 125 | O15: 2029 promo one-year (gap to 230) | P15: =MAX(Assumptions!$C$5*Assumptions!$C$12,S11-(S12)) -> 130 | S15: =$P15*Assumptions!$C$21 -> 130 | T15: =$P15*Assumptions!$D$21 -> 0 | U15: =$P15*Assumptions!$E$21 -> 0 | V15: =$P15*Assumptions!$F$21 -> 0 | Z15: =$P15*Assumptions!$G$21 -> 130
B16: 2030 transition 100/15/5/5 (gap to 200) | C16: =MAX(Assumptions!$C$5*Assumptions!$C$12,G11-(G12)) -> 200 | G16: =$C16*Assumptions!$C$17 -> 200 | H16: =$C16*Assumptions!$D$17 -> 30 | I16: =$C16*Assumptions!$E$17 -> 10 | J16: =$C16*Assumptions!$F$17 -> 10 | M16: =$C16*Assumptions!$G$17 -> 250 | O16: 2030 transition 100/50 at 230 | P16: =Assumptions!$C$10 -> 230 | T16: =$P16*Assumptions!$C$19 -> 230 | U16: =$P16*Assumptions!$D$19 -> 115 | V16: =$P16*Assumptions!$E$19 -> 0 | W16: =$P16*Assumptions!$F$19 -> 0 | Z16: =$P16*Assumptions!$G$19 -> 345
B17: 2031 refresh 200/30/10/10 | C17: =Assumptions!$C$5*Assumptions!$C$8 -> 200 | H17: =$C17*Assumptions!$C$17 -> 200 | I17: =$C17*Assumptions!$D$17 -> 30 | J17: =$C17*Assumptions!$E$17 -> 10 | K17: =$C17*Assumptions!$F$17 -> 10 | M17: =$C17*Assumptions!$G$17 -> 250 | O17: 2031 refresh 50/50 at 230 | P17: =Assumptions!$C$11*Assumptions!$C$10 -> 115 | U17: =$P17*Assumptions!$C$18 -> 115 | V17: =$P17*Assumptions!$D$18 -> 115 | W17: =$P17*Assumptions!$E$18 -> 0 | X17: =$P17*Assumptions!$F$18 -> 0 | Z17: =$P17*Assumptions!$G$18 -> 230
B18: 2032 refresh 200/30/10/10 | C18: =Assumptions!$C$5*Assumptions!$C$8 -> 200 | I18: =$C18*Assumptions!$C$17 -> 200 | J18: =$C18*Assumptions!$D$17 -> 30 | K18: =$C18*Assumptions!$E$17 -> 10 | L18: =$C18*Assumptions!$F$17 -> 10 | M18: =$C18*Assumptions!$G$17 -> 250 | O18: 2032 refresh 50/50 at 230 | P18: =Assumptions!$C$11*Assumptions!$C$10 -> 115 | V18: =$P18*Assumptions!$C$18 -> 115 | W18: =$P18*Assumptions!$D$18 -> 115 | X18: =$P18*Assumptions!$E$18 -> 0 | Y18: =$P18*Assumptions!$F$18 -> 0 | Z18: =$P18*Assumptions!$G$18 -> 230
B19: 2033 refresh 200/30/10/10 | C19: =Assumptions!$C$5*Assumptions!$C$8 -> 200 | J19: =$C19*Assumptions!$C$17 -> 200 | K19: =$C19*Assumptions!$D$17 -> 30 | L19: =$C19*Assumptions!$E$17 -> 10 | M19: =$C19*Assumptions!$G$17 -> 250 | O19: 2033 refresh 50/50 at 230 | P19: =Assumptions!$C$11*Assumptions!$C$10 -> 115 | W19: =$P19*Assumptions!$C$18 -> 115 | X19: =$P19*Assumptions!$D$18 -> 115 | Y19: =$P19*Assumptions!$E$18 -> 0 | Z19: =$P19*Assumptions!$G$18 -> 230
B20: 2034 refresh 200/30/10/10 | C20: =Assumptions!$C$5*Assumptions!$C$8 -> 200 | K20: =$C20*Assumptions!$C$17 -> 200 | L20: =$C20*Assumptions!$D$17 -> 30 | M20: =$C20*Assumptions!$G$17 -> 250 | O20: 2034 refresh 50/50 at 230 | P20: =Assumptions!$C$11*Assumptions!$C$10 -> 115 | X20: =$P20*Assumptions!$C$18 -> 115 | Y20: =$P20*Assumptions!$D$18 -> 115 | Z20: =$P20*Assumptions!$G$18 -> 230
B21: 2035 refresh 200/30/10/10 | C21: =Assumptions!$C$5*Assumptions!$C$8 -> 200 | L21: =$C21*Assumptions!$C$17 -> 200 | M21: =$C21*Assumptions!$G$17 -> 250 | O21: 2035 refresh 50/50 at 230 | P21: =Assumptions!$C$11*Assumptions!$C$10 -> 115 | Y21: =$P21*Assumptions!$C$18 -> 115 | Z21: =$P21*Assumptions!$G$18 -> 230
B22: Total annual vest | C22: Total | D22: =D12+SUM(D13:D21) -> 125 | E22: =E12+SUM(E13:E21) -> 128.75 | F22: =F12+SUM(F13:F21) -> 205 | G22: =G12+SUM(G13:G21) -> 217.5 | H22: =H12+SUM(H13:H21) -> 236.25 | I22: =I12+SUM(I13:I21) -> 245 | J22: =J12+SUM(J13:J21) -> 250 | K22: =K12+SUM(K13:K21) -> 250 | L22: =L12+SUM(L13:L21) -> 250 | M22: =SUM(M13:M21) -> 1687.5 | O22: Total annual vest | P22: Total | Q22: =Q12+SUM(Q13:Q21) -> 125 | R22: =R12+SUM(R13:R21) -> 125 | S22: =S12+SUM(S13:S21) -> 230 | T22: =T12+SUM(T13:T21) -> 230 | U22: =U12+SUM(U13:U21) -> 230 | V22: =V12+SUM(V13:V21) -> 230 | W22: =W12+SUM(W13:W21) -> 230 | X22: =X12+SUM(X13:X21) -> 230 | Y22: =Y12+SUM(Y13:Y21) -> 230 | Z22: =SUM(Z13:Z21) -> 1675
B23: % of steady-state ceiling | D23: =D22/D11 -> 1 | E23: =E22/E11 -> 1.03 | F23: =F22/F11 -> 1.025 | G23: =G22/G11 -> 1.0875 | H23: =H22/H11 -> 1.89 | I23: =I22/I11 -> 1.96 | J23: =J22/J11 -> 2 | K23: =K22/K11 -> 2 | L23: =L22/L11 -> 2 | O23: % of steady-state ceiling | Q23: =Q22/Q11 -> 1 | R23: =R22/R11 -> 1 | S23: =S22/S11 -> 1 | T23: =T22/T11 -> 1 | U23: =U22/U11 -> 1.84 | V23: =V22/V11 -> 1.84 | W23: =W22/W11 -> 1.84 | X23: =X22/X11 -> 1.84 | Y23: =Y22/Y11 -> 1.84
B24: Change vs prior year | D24: =D22-Assumptions!$C$5 -> 25 | E24: =E22-D22 -> 3.75 | F24: =F22-E22 -> 76.25 | G24: =G22-F22 -> 12.5 | H24: =H22-G22 -> 18.75 | I24: =I22-H22 -> 8.75 | J24: =J22-I22 -> 5 | K24: =K22-J22 -> 0 | L24: =L22-K22 -> 0 | O24: Change vs prior year | Q24: =Q22-Assumptions!$C$5 -> 25 | R24: =R22-Q22 -> 0 | S24: =S22-R22 -> 105 | T24: =T22-S22 -> 0 | U24: =U22-T22 -> 0 | V24: =V22-U22 -> 0 | W24: =W22-V22 -> 0 | X24: =X22-W22 -> 0 | Y24: =Y22-X22 -> 0
B28: Persona C hired 2026, 25 of target vesting in the transition year transition year 2030
B29: Option 1 100/15/5/5 | C29: Sizing | D29: 2027 | E29: 2028 | F29: 2029 | G29: 2030 | H29: 2031 | I29: 2032 | J29: 2033 | K29: 2034 | L29: 2035 | M29: Face | O29: Option 2 100/50 and 50/50 | P29: Sizing | Q29: 2027 | R29: 2028 | S29: 2029 | T29: 2030 | U29: 2031 | V29: 2032 | W29: 2033 | X29: 2034 | Y29: 2035 | Z29: Face
B30: Gap target (used only in T and promo years) | D30: =Assumptions!$C$5*Assumptions!$C$6 -> 125 | E30: =Assumptions!$C$5*Assumptions!$C$6 -> 125 | F30: =Assumptions!$C$5*Assumptions!$C$8 -> 200 | G30: =Assumptions!$C$5*Assumptions!$C$8 -> 200 | H30: =Assumptions!$C$5*Assumptions!$C$6 -> 125 | I30: =Assumptions!$C$5*Assumptions!$C$6 -> 125 | J30: =Assumptions!$C$5*Assumptions!$C$6 -> 125 | K30: =Assumptions!$C$5*Assumptions!$C$6 -> 125 | L30: =Assumptions!$C$5*Assumptions!$C$6 -> 125 | O30: Gap target (used only in T and promo years) | Q30: =Assumptions!$C$5*Assumptions!$C$6 -> 125 | R30: =Assumptions!$C$5*Assumptions!$C$6 -> 125 | S30: =Assumptions!$C$10 -> 230 | T30: =Assumptions!$C$10 -> 230 | U30: =Assumptions!$C$5*Assumptions!$C$6 -> 125 | V30: =Assumptions!$C$5*Assumptions!$C$6 -> 125 | W30: =Assumptions!$C$5*Assumptions!$C$6 -> 125 | X30: =Assumptions!$C$5*Assumptions!$C$6 -> 125 | Y30: =Assumptions!$C$5*Assumptions!$C$6 -> 125
B31: Legacy scheduled vest | D31: 100 | E31: 100 | F31: 100 | G31: 25 | H31: 0 | I31: 0 | J31: 0 | K31: 0 | L31: 0 | O31: Legacy scheduled vest | Q31: 100 | R31: 100 | S31: 100 | T31: 25 | U31: 0 | V31: 0 | W31: 0 | X31: 0 | Y31: 0
B32: 2027 pre-transition top-up | C32: =MAX(Assumptions!$C$5*Assumptions!$C$12,D30-(D31)) -> 25 | D32: =$C32*Assumptions!$C$23 -> 25 | E32: =$C32*Assumptions!$D$23 -> 3.75 | F32: =$C32*Assumptions!$E$23 -> 1.25 | G32: =$C32*Assumptions!$F$23 -> 1.25 | M32: =$C32*Assumptions!$G$23 -> 31.25 | O32: 2027 pre-transition top-up (1 year) | P32: =MAX(Assumptions!$C$5*Assumptions!$C$12,Q30-(Q31)) -> 25 | Q32: =$P32*Assumptions!$C$21 -> 25 | R32: =$P32*Assumptions!$D$21 -> 0 | S32: =$P32*Assumptions!$E$21 -> 0 | T32: =$P32*Assumptions!$F$21 -> 0 | Z32: =$P32*Assumptions!$G$21 -> 25
B33: 2028 pre-transition top-up | C33: =MAX(Assumptions!$C$5*Assumptions!$C$12,E30-(E31)) -> 25 | E33: =$C33*Assumptions!$C$23 -> 25 | F33: =$C33*Assumptions!$D$23 -> 3.75 | G33: =$C33*Assumptions!$E$23 -> 1.25 | H33: =$C33*Assumptions!$F$23 -> 1.25 | M33: =$C33*Assumptions!$G$23 -> 31.25 | O33: 2028 pre-transition top-up (1 year) | P33: =MAX(Assumptions!$C$5*Assumptions!$C$12,R30-(R31)) -> 25 | R33: =$P33*Assumptions!$C$21 -> 25 | S33: =$P33*Assumptions!$D$21 -> 0 | T33: =$P33*Assumptions!$E$21 -> 0 | U33: =$P33*Assumptions!$F$21 -> 0 | Z33: =$P33*Assumptions!$G$21 -> 25
B34: 2029 promo grant (gap to 200) | C34: =MAX(Assumptions!$C$5*Assumptions!$C$12,F30-(F31)) -> 100 | F34: =$C34*Assumptions!$C$23 -> 100 | G34: =$C34*Assumptions!$D$23 -> 15 | H34: =$C34*Assumptions!$E$23 -> 5 | I34: =$C34*Assumptions!$F$23 -> 5 | M34: =$C34*Assumptions!$G$23 -> 125 | O34: 2029 promo one-year (gap to 230) | P34: =MAX(Assumptions!$C$5*Assumptions!$C$12,S30-(S31)) -> 130 | S34: =$P34*Assumptions!$C$21 -> 130 | T34: =$P34*Assumptions!$D$21 -> 0 | U34: =$P34*Assumptions!$E$21 -> 0 | V34: =$P34*Assumptions!$F$21 -> 0 | Z34: =$P34*Assumptions!$G$21 -> 130
B35: 2030 transition 100/15/5/5 (gap to 200) | C35: =MAX(Assumptions!$C$5*Assumptions!$C$12,G30-(G31)) -> 175 | G35: =$C35*Assumptions!$C$17 -> 175 | H35: =$C35*Assumptions!$D$17 -> 26.25 | I35: =$C35*Assumptions!$E$17 -> 8.75 | J35: =$C35*Assumptions!$F$17 -> 8.75 | M35: =$C35*Assumptions!$G$17 -> 218.75 | O35: 2030 transition Grant 1 (gap) | P35: =T30-(T31+$P36) -> 90 | T35: =$P35*Assumptions!$C$21 -> 90 | U35: =$P35*Assumptions!$D$21 -> 0 | V35: =$P35*Assumptions!$E$21 -> 0 | W35: =$P35*Assumptions!$F$21 -> 0 | Z35: =$P35*Assumptions!$G$21 -> 90
B36: 2031 refresh 200/30/10/10 | C36: =Assumptions!$C$5*Assumptions!$C$8 -> 200 | H36: =$C36*Assumptions!$C$17 -> 200 | I36: =$C36*Assumptions!$D$17 -> 30 | J36: =$C36*Assumptions!$E$17 -> 10 | K36: =$C36*Assumptions!$F$17 -> 10 | M36: =$C36*Assumptions!$G$17 -> 250 | O36: 2030 transition Grant 2 2-yr equal | P36: =Assumptions!$C$11*Assumptions!$C$10 -> 115 | T36: =$P36*Assumptions!$C$18 -> 115 | U36: =$P36*Assumptions!$D$18 -> 115 | V36: =$P36*Assumptions!$E$18 -> 0 | W36: =$P36*Assumptions!$F$18 -> 0 | Z36: =$P36*Assumptions!$G$18 -> 230
B37: 2032 refresh 200/30/10/10 | C37: =Assumptions!$C$5*Assumptions!$C$8 -> 200 | I37: =$C37*Assumptions!$C$17 -> 200 | J37: =$C37*Assumptions!$D$17 -> 30 | K37: =$C37*Assumptions!$E$17 -> 10 | L37: =$C37*Assumptions!$F$17 -> 10 | M37: =$C37*Assumptions!$G$17 -> 250 | O37: 2031 refresh 50/50 at 230 | P37: =Assumptions!$C$11*Assumptions!$C$10 -> 115 | U37: =$P37*Assumptions!$C$18 -> 115 | V37: =$P37*Assumptions!$D$18 -> 115 | W37: =$P37*Assumptions!$E$18 -> 0 | X37: =$P37*Assumptions!$F$18 -> 0 | Z37: =$P37*Assumptions!$G$18 -> 230
B38: 2033 refresh 200/30/10/10 | C38: =Assumptions!$C$5*Assumptions!$C$8 -> 200 | J38: =$C38*Assumptions!$C$17 -> 200 | K38: =$C38*Assumptions!$D$17 -> 30 | L38: =$C38*Assumptions!$E$17 -> 10 | M38: =$C38*Assumptions!$G$17 -> 250 | O38: 2032 refresh 50/50 at 230 | P38: =Assumptions!$C$11*Assumptions!$C$10 -> 115 | V38: =$P38*Assumptions!$C$18 -> 115 | W38: =$P38*Assumptions!$D$18 -> 115 | X38: =$P38*Assumptions!$E$18 -> 0 | Y38: =$P38*Assumptions!$F$18 -> 0 | Z38: =$P38*Assumptions!$G$18 -> 230
B39: 2034 refresh 200/30/10/10 | C39: =Assumptions!$C$5*Assumptions!$C$8 -> 200 | K39: =$C39*Assumptions!$C$17 -> 200 | L39: =$C39*Assumptions!$D$17 -> 30 | M39: =$C39*Assumptions!$G$17 -> 250 | O39: 2033 refresh 50/50 at 230 | P39: =Assumptions!$C$11*Assumptions!$C$10 -> 115 | W39: =$P39*Assumptions!$C$18 -> 115 | X39: =$P39*Assumptions!$D$18 -> 115 | Y39: =$P39*Assumptions!$E$18 -> 0 | Z39: =$P39*Assumptions!$G$18 -> 230
B40: 2035 refresh 200/30/10/10 | C40: =Assumptions!$C$5*Assumptions!$C$8 -> 200 | L40: =$C40*Assumptions!$C$17 -> 200 | M40: =$C40*Assumptions!$G$17 -> 250 | O40: 2034 refresh 50/50 at 230 | P40: =Assumptions!$C$11*Assumptions!$C$10 -> 115 | X40: =$P40*Assumptions!$C$18 -> 115 | Y40: =$P40*Assumptions!$D$18 -> 115 | Z40: =$P40*Assumptions!$G$18 -> 230
